[2024-01-09T10:39:53.627-0300] {taskinstance.py:1957} INFO - Dependencies all met for dep_context=non-requeueable deps ti=<TaskInstance: pokemon_extraction.extract_pokemons scheduled__2023-10-30T10:00:00+00:00 [queued]>
[2024-01-09T10:39:53.630-0300] {taskinstance.py:1957} INFO - Dependencies all met for dep_context=requeueable deps ti=<TaskInstance: pokemon_extraction.extract_pokemons scheduled__2023-10-30T10:00:00+00:00 [queued]>
[2024-01-09T10:39:53.630-0300] {taskinstance.py:2171} INFO - Starting attempt 1 of 1
[2024-01-09T10:39:53.642-0300] {taskinstance.py:2192} INFO - Executing <Task(PythonOperator): extract_pokemons> on 2023-10-30 10:00:00+00:00
[2024-01-09T10:39:53.644-0300] {standard_task_runner.py:60} INFO - Started process 3941 to run task
[2024-01-09T10:39:53.645-0300] {standard_task_runner.py:87} INFO - Running: ['airflow', 'tasks', 'run', 'pokemon_extraction', 'extract_pokemons', 'scheduled__2023-10-30T10:00:00+00:00', '--job-id', '238', '--raw', '--subdir', 'DAGS_FOLDER/pokemon_extraction.py', '--cfg-path', '/tmp/tmpjqq5l3s4']
[2024-01-09T10:39:53.646-0300] {standard_task_runner.py:88} INFO - Job 238: Subtask extract_pokemons
[2024-01-09T10:39:53.668-0300] {task_command.py:423} INFO - Running <TaskInstance: pokemon_extraction.extract_pokemons scheduled__2023-10-30T10:00:00+00:00 [running]> on host LAPTOP-SB6KEOGH.
[2024-01-09T10:39:53.713-0300] {taskinstance.py:2481} INFO - Exporting env vars: AIRFLOW_CTX_DAG_OWNER='Brenda Schapievski' AIRFLOW_CTX_DAG_ID='pokemon_extraction' AIRFLOW_CTX_TASK_ID='extract_pokemons' AIRFLOW_CTX_EXECUTION_DATE='2023-10-30T10:00:00+00:00' AIRFLOW_CTX_TRY_NUMBER='1' AIRFLOW_CTX_DAG_RUN_ID='scheduled__2023-10-30T10:00:00+00:00'
[2024-01-09T10:39:54.017-0300] {taskinstance.py:2699} ERROR - Task failed with exception
Traceback (most recent call last):
  File "/home/brendaschap/.local/lib/python3.10/site-packages/airflow/models/taskinstance.py", line 433, in _execute_task
    result = execute_callable(context=context, **execute_callable_kwargs)
  File "/home/brendaschap/.local/lib/python3.10/site-packages/airflow/operators/python.py", line 199, in execute
    return_value = self.execute_callable()
  File "/home/brendaschap/.local/lib/python3.10/site-packages/airflow/operators/python.py", line 216, in execute_callable
    return self.python_callable(*self.op_args, **self.op_kwargs)
  File "/home/brendaschap/airflow/dags/pokemon.py", line 22, in extract_pokemon
    pokemon_list.append(infos)
NameError: name 'infos' is not defined
[2024-01-09T10:39:54.021-0300] {taskinstance.py:1138} INFO - Marking task as FAILED. dag_id=pokemon_extraction, task_id=extract_pokemons, execution_date=20231030T100000, start_date=20240109T133953, end_date=20240109T133954
[2024-01-09T10:39:54.036-0300] {standard_task_runner.py:107} ERROR - Failed to execute job 238 for task extract_pokemons (name 'infos' is not defined; 3941)
[2024-01-09T10:39:54.058-0300] {local_task_job_runner.py:234} INFO - Task exited with return code 1
[2024-01-09T10:39:54.069-0300] {taskinstance.py:3281} INFO - 0 downstream tasks scheduled from follow-on schedule check
